<?xml version="1.0" ?>
<robot name="01" xmlns:xacro="http://www.ros.org/wiki/xacro">

<xacro:macro name="01" params="prefix">

<xacro:include filename="$(find 01_description)/urdf/materials.xacro" />
<xacro:include filename="$(find 01_description)/urdf/01.trans" />
<xacro:include filename="$(find 01_description)/urdf/01.gazebo" />
<link name="${prefix}base_link"/>

<link name="${prefix}Component2">
  <inertial>
    <origin xyz="0.004007878054801701 0.0 0.02285970465052938" rpy="0 0 0"/>
    <mass value="0.4996098649177568"/>
    <inertia ixx="0.000131" iyy="0.000147" izz="0.000117" ixy="0.0" iyz="0.0" ixz="-1.7e-05"/>
  </inertial>
  <visual>
    <origin xyz="0 0 0" rpy="0 0 0"/>
    <geometry>
      <mesh filename="package://01_description/meshes/Component2.stl" scale="0.001 0.001 0.001"/>
    </geometry>
    <material name="01_silver"/>
  </visual>
  <collision>
    <origin xyz="0 0 0" rpy="0 0 0"/>
    <geometry>
      <mesh filename="package://01_description/meshes/Component2.stl" scale="0.001 0.001 0.001"/>
    </geometry>
  </collision>
</link>

<joint name="${prefix}È¸Àü 1" type="continuous">
  <origin xyz="0.0 0.0 0.005" rpy="0 0 0"/>
  <parent link="${prefix}base_link"/>
  <child link="${prefix}Component2"/>
  <axis xyz="0.0 0.0 1.0"/>
</joint>

</xacro:macro>
</robot>
