<?xml version='1.0' encoding='utf-8'?>
<robot name="sfbot">
    <link name="base_link">
        <inertial>
            <origin xyz="0.0013386396517363875 -0.0011242493747386578 0.009051092998347913" rpy="0.0 0.0 0.0" />
            <mass value="3.888884702652834" />
            <inertia ixx="0.010759968313061485" iyy="0.010736881042533725" izz="0.020894462545599256" ixy="0.00021664303992281595" iyz="0.00020888253586269707" ixz="-0.00017260000031820458" />
        </inertial>
        <visual name="base_link_visual">
            <origin xyz="0.0 0.0 0.0" rpy="0.0 0.0 0.0" />
            <geometry>
                <mesh filename="meshes/base_link.stl" scale="0.001 0.001 0.001" />
            </geometry>
        </visual>
        <collision name="base_link_collision">
            <origin xyz="0.0 0.0 0.0" rpy="0.0 0.0 0.0" />
            <geometry>
                <mesh filename="meshes/base_link.stl" scale="0.001 0.001 0.001" />
            </geometry>
        </collision>
    </link>
    <link name="Component2">
        <inertial>
            <origin xyz="0.010945074522192507 1.6285806493933998e-05 -0.00012479722831548246" rpy="0.0 -0.0 0.0" />
            <mass value="1.0016922735671667" />
            <inertia ixx="0.0011260395358370881" iyy="0.0005973385271454308" izz="0.0005917945399063129" ixy="1.0527145733118499e-07" iyz="7.360388447256132e-07" ixz="-8.067346046123616e-07" />
        </inertial>
        <visual name="Component2_visual">
            <origin xyz="-0.06300000093876953 9.933979985053653e-18 -1.058454243043459e-16" rpy="1.5707963267947935 1.5283000565118283 1.5707963267947935" />
            <geometry>
                <mesh filename="meshes/Component2.stl" scale="0.001 0.001 0.001" />
            </geometry>
        </visual>
        <collision name="Component2_collision">
            <origin xyz="-0.06300000093876953 9.933979985053653e-18 -1.058454243043459e-16" rpy="1.5707963267947935 1.5283000565118283 1.5707963267947935" />
            <geometry>
                <mesh filename="meshes/Component2.stl" scale="0.001 0.001 0.001" />
            </geometry>
        </collision>
    </link>
    <link name="Component3">
        <inertial>
            <origin xyz="-0.0007886424011557253 0.0015580377035300363 0.008375687022007288" rpy="0.0 -0.0 1.7516230804060217e-46" />
            <mass value="0.8807950300955173" />
            <inertia ixx="0.0005344758739841621" iyy="0.0005081402472842899" izz="0.0009807519381804836" ixy="2.729301839018179e-05" iyz="-1.9642096063161785e-05" ixz="9.942924608684108e-06" />
        </inertial>
        <visual name="Component3_visual">
            <origin xyz="-1.3108966917960693e-16 -1.242785109918427e-17 -0.08500000126659525" rpy="-3.797673495120442e-16 -4.476643978342218e-15 -3.099096383306725" />
            <geometry>
                <mesh filename="meshes/Component3.stl" scale="0.001 0.001 0.001" />
            </geometry>
        </visual>
        <collision name="Component3_collision">
            <origin xyz="-1.3108966917960693e-16 -1.242785109918427e-17 -0.08500000126659525" rpy="-3.797673495120442e-16 -4.476643978342218e-15 -3.099096383306725" />
            <geometry>
                <mesh filename="meshes/Component3.stl" scale="0.001 0.001 0.001" />
            </geometry>
        </collision>
    </link>
    <link name="Component4">
        <inertial>
            <origin xyz="0.013748075737572083 -0.029760560473953902 -0.019811113493130694" rpy="0.0 -0.0 0.0" />
            <mass value="0.6184682868789885" />
            <inertia ixx="0.0005440588677829115" iyy="0.0007775141443192041" izz="0.0005760836245136454" ixy="9.94493658961855e-06" iyz="-7.625684554984325e-05" ixz="-3.242583717352708e-06" />
        </inertial>
        <visual name="Component4_visual">
            <origin xyz="0.013882699999999628 -0.026594559999999927 0.10326725730081326" rpy="3.1415926535897927 6.881253629370109e-15 3.099096383306725" />
            <geometry>
                <mesh filename="meshes/Component4.stl" scale="0.001 0.001 0.001" />
            </geometry>
        </visual>
        <collision name="Component4_collision">
            <origin xyz="0.013882699999999628 -0.026594559999999927 0.10326725730081326" rpy="3.1415926535897927 6.881253629370109e-15 3.099096383306725" />
            <geometry>
                <mesh filename="meshes/Component4.stl" scale="0.001 0.001 0.001" />
            </geometry>
        </collision>
    </link>
    <link name="Component5">
        <inertial>
            <origin xyz="-0.0006683018280100761 -0.015323952737990624 -0.0009955978719707942" rpy="3.0920838838475396e-90 -0.0 0.0" />
            <mass value="0.6082106863628858" />
            <inertia ixx="0.0002283636801850259" iyy="0.00041029589506225313" izz="0.00024020671057143125" ixy="-1.5470283656494187e-06" iyz="6.2705694062590345e-06" ixz="-8.085207438949547e-06" />
        </inertial>
        <visual name="Component5_visual">
            <origin xyz="-0.15112264860497968 0.023513786425360186 0.035483063201822256" rpy="2.952570499959834 1.3427262874177526 2.957353884887777" />
            <geometry>
                <mesh filename="meshes/Component5.stl" scale="0.001 0.001 0.001" />
            </geometry>
        </visual>
        <collision name="Component5_collision">
            <origin xyz="-0.15112264860497968 0.023513786425360186 0.035483063201822256" rpy="2.952570499959834 1.3427262874177526 2.957353884887777" />
            <geometry>
                <mesh filename="meshes/Component5.stl" scale="0.001 0.001 0.001" />
            </geometry>
        </collision>
    </link>
    <link name="Component6">
        <inertial>
            <origin xyz="-0.00283291994658379 -0.014279646362181226 -0.0006009546680233323" rpy="3.0920838838475396e-90 -0.0 0.0" />
            <mass value="0.8292297988354185" />
            <inertia ixx="0.0005834388068200032" iyy="0.000940986734438924" izz="0.0004391059977545477" ixy="1.4543106151553362e-05" iyz="2.1347417445775976e-05" ixz="3.9047361154298364e-07" />
        </inertial>
        <visual name="Component6_visual">
            <origin xyz="-0.1602672573008139 4.5346505506138615e-09 -7.916735501878325e-10" rpy="-1.570796326795061 -1.5283000565118345 -1.5707963267947436" />
            <geometry>
                <mesh filename="meshes/Component6.stl" scale="0.001 0.001 0.001" />
            </geometry>
        </visual>
        <collision name="Component6_collision">
            <origin xyz="-0.1602672573008139 4.5346505506138615e-09 -7.916735501878325e-10" rpy="-1.570796326795061 -1.5283000565118345 -1.5707963267947436" />
            <geometry>
                <mesh filename="meshes/Component6.stl" scale="0.001 0.001 0.001" />
            </geometry>
        </collision>
    </link>
    <link name="Component7">
        <inertial>
            <origin xyz="0.007006378712017978 0.031687009999977304 0.005267280345113026" rpy="0.0 4.900087475557542e-36 0.0" />
            <mass value="0.3722794963916967" />
            <inertia ixx="0.0001513862134997681" iyy="0.000151124726077434" izz="0.00029574396422002436" ixy="-1.6813181237022939e-15" iyz="-9.410901830827886e-17" ixz="-6.149480527738623e-06" />
        </inertial>
        <visual name="Component7_visual">
            <origin xyz="0.04488011447535868 0.1879451522390213 -0.046910693962991364" rpy="-1.5802474444259964 0.04143260168547573 2.917253219840132" />
            <geometry>
                <mesh filename="meshes/Component7.stl" scale="0.001 0.001 0.001" />
            </geometry>
        </visual>
        <collision name="Component7_collision">
            <origin xyz="0.04488011447535868 0.1879451522390213 -0.046910693962991364" rpy="-1.5802474444259964 0.04143260168547573 2.917253219840132" />
            <geometry>
                <mesh filename="meshes/Component7.stl" scale="0.001 0.001 0.001" />
            </geometry>
        </collision>
    </link>
    <link name="Component8_1">
        <inertial>
            <origin xyz="-0.00690583795406051 -0.02957613551442201 0.0036957106611801827" rpy="0.0 -1.5160522143184804e-35 0.0" />
            <mass value="0.668762166036501" />
            <inertia ixx="0.000835974177007804" iyy="0.0002507272281283253" izz="0.001063437389544012" ixy="-0.00013948888765160077" iyz="-2.7598304358783174e-05" ixz="-1.4642613929968098e-05" />
        </inertial>
        <visual name="Component8_1_visual">
            <origin xyz="0.00444141905803777 0.019499699999979577 0.00018885992793549633" rpy="-1.5802474444259917 0.041432601685469826 2.917253219840132" />
            <geometry>
                <mesh filename="meshes/Component8_1.stl" scale="0.001 0.001 0.001" />
            </geometry>
        </visual>
        <collision name="Component8_1_collision">
            <origin xyz="0.00444141905803777 0.019499699999979577 0.00018885992793549633" rpy="-1.5802474444259917 0.041432601685469826 2.917253219840132" />
            <geometry>
                <mesh filename="meshes/Component8_1.stl" scale="0.001 0.001 0.001" />
            </geometry>
        </collision>
    </link>
    <link name="Component8_2">
        <inertial>
            <origin xyz="0.02491339764481104 -0.03896036448562473 0.01093722058016815" rpy="0.0 2.5712046134349837e-35 0.0" />
            <mass value="0.668762166036501" />
            <inertia ixx="0.0008351363010562426" iyy="0.00025072722812836284" izz="0.0010642752654957469" ixy="0.00014132820266159887" iyz="1.565743638736166e-05" ixz="4.8081338281474795e-06" />
        </inertial>
        <visual name="Component8_2_visual">
            <origin xyz="0.03592199711487428 -0.08803620000002452 0.006479757010847393" rpy="-1.5613452091637934 0.04143260168547171 0.2243394337496614" />
            <geometry>
                <mesh filename="meshes/Component8_2.stl" scale="0.001 0.001 0.001" />
            </geometry>
        </visual>
        <collision name="Component8_2_collision">
            <origin xyz="0.03592199711487428 -0.08803620000002452 0.006479757010847393" rpy="-1.5613452091637934 0.04143260168547171 0.2243394337496614" />
            <geometry>
                <mesh filename="meshes/Component8_2.stl" scale="0.001 0.001 0.001" />
            </geometry>
        </collision>
    </link>
    <link name="Component9">
        <inertial>
            <origin xyz="0.02381012518298724 -0.001902418356107347 0.04102426678092323" rpy="0.0 -0.0 0.0" />
            <mass value="0.6867109263567744" />
            <inertia ixx="0.0006809371140334213" iyy="0.0010712609425767262" izz="0.0005335158092448708" ixy="-9.19027074675564e-05" iyz="3.921162863849024e-06" ixz="-6.2625620898511106e-06" />
        </inertial>
        <visual name="Component9_visual">
            <origin xyz="0.014937281565715286 0.010437266529327296 0.04140278801916261" rpy="1.5613452091544993 -0.04143260172380087 -2.917253219839769" />
            <geometry>
                <mesh filename="meshes/Component9.stl" scale="0.001 0.001 0.001" />
            </geometry>
        </visual>
        <collision name="Component9_collision">
            <origin xyz="0.014937281565715286 0.010437266529327296 0.04140278801916261" rpy="1.5613452091544993 -0.04143260172380087 -2.917253219839769" />
            <geometry>
                <mesh filename="meshes/Component9.stl" scale="0.001 0.001 0.001" />
            </geometry>
        </collision>
    </link>
    <link name="ak60-6v1-1-v1">
        <inertial>
            <origin xyz="-0.002223859649423825 -9.456075803689679e-05 0.01066111405575171" rpy="0.0 -0.0 2.5712046134360785e-35" />
            <mass value="1.2585201056414106" />
            <inertia ixx="0.0005942666230154131" iyy="0.0005748730048051182" izz="0.0008790346768159633" ixy="8.261466880735511e-07" iyz="-2.7185216081057465e-06" ixz="-6.39323145513685e-05" />
        </inertial>
        <visual name="ak60-6v1-1-v1_visual">
            <origin xyz="0.002331745018496494 9.915207426362982e-05 -0.010237344029911171" rpy="1.5707963267972924 1.346652714712254 0.04249627032481174" />
            <geometry>
                <mesh filename="meshes/ak60-6v1-1-v1.stl" scale="0.001 0.001 0.001" />
            </geometry>
        </visual>
        <collision name="ak60-6v1-1-v1_collision">
            <origin xyz="0.002331745018496494 9.915207426362982e-05 -0.010237344029911171" rpy="1.5707963267972924 1.346652714712254 0.04249627032481174" />
            <geometry>
                <mesh filename="meshes/ak60-6v1-1-v1.stl" scale="0.001 0.001 0.001" />
            </geometry>
        </collision>
    </link>
    <link name="Component10">
        <inertial>
            <origin xyz="0.0025667194475102306 -0.002750576351406728 -0.002391640131544528" rpy="6.167813476837256e-33 3.851859888774472e-34 0.0" />
            <mass value="0.13156890942165747" />
            <inertia ixx="0.00014187845116143995" iyy="7.04248240889684e-05" izz="7.85559594578041e-05" ixy="1.0580260557738733e-06" iyz="-5.916131696761643e-06" ixz="-1.3998681776128697e-05" />
        </inertial>
        <visual name="Component10_visual">
            <origin xyz="-1.0529217675525615e-09 -3.1647141796042887e-09 4.4273204835576505e-09" rpy="2.952570499788471 1.3427262874105512 2.957353884721262" />
            <geometry>
                <mesh filename="meshes/Component10.stl" scale="0.001 0.001 0.001" />
            </geometry>
        </visual>
        <collision name="Component10_collision">
            <origin xyz="-1.0529217675525615e-09 -3.1647141796042887e-09 4.4273204835576505e-09" rpy="2.952570499788471 1.3427262874105512 2.957353884721262" />
            <geometry>
                <mesh filename="meshes/Component10.stl" scale="0.001 0.001 0.001" />
            </geometry>
        </collision>
    </link>
    <link name="Component11">
        <inertial>
            <origin xyz="0.010316014057783783 5.3006671664499464e-05 -0.0023905320339148873" rpy="6.167813476837256e-33 3.851859888774472e-34 0.0" />
            <mass value="0.3456856671384452" />
            <inertia ixx="0.00014934500554077303" iyy="8.596864608930233e-05" izz="8.934960698369837e-05" ixy="5.142923150115669e-07" iyz="-3.880136900106562e-07" ixz="-1.4449577025472685e-05" />
        </inertial>
        <visual name="Component11_visual">
            <origin xyz="-4.508141628889462e-09 1.1277805789244866e-09 -1.625800041260561e-09" rpy="-1.861486937139929 0.6843848763043473 -1.748034659226887" />
            <geometry>
                <mesh filename="meshes/Component11.stl" scale="0.001 0.001 0.001" />
            </geometry>
        </visual>
        <collision name="Component11_collision">
            <origin xyz="-4.508141628889462e-09 1.1277805789244866e-09 -1.625800041260561e-09" rpy="-1.861486937139929 0.6843848763043473 -1.748034659226887" />
            <geometry>
                <mesh filename="meshes/Component11.stl" scale="0.001 0.001 0.001" />
            </geometry>
        </collision>
    </link>
    <link name="ak70-10-v1_1">
        <inertial>
            <origin xyz="-7.146546050766822e-05 7.146546059160694e-05 0.014729945989910722" rpy="0.0 -0.0 0.0" />
            <mass value="2.1429063401431327" />
            <inertia ixx="0.001352590595148548" iyy="0.0013525905928285895" izz="0.001943353163998447" ixy="-3.36623600805629e-06" iyz="3.3580222740980733e-06" ixz="-3.3580222738421545e-06" />
        </inertial>
        <visual name="ak70-10-v1_1_visual">
            <origin xyz="-4.884981308350689e-17 0.0 -0.011199999999999996" rpy="-0.0 1.5707963267948923 0" />
            <geometry>
                <mesh filename="meshes/ak70-10-v1_1.stl" scale="0.001 0.001 0.001" />
            </geometry>
        </visual>
        <collision name="ak70-10-v1_1_collision">
            <origin xyz="-4.884981308350689e-17 0.0 -0.011199999999999996" rpy="-0.0 1.5707963267948923 0" />
            <geometry>
                <mesh filename="meshes/ak70-10-v1_1.stl" scale="0.001 0.001 0.001" />
            </geometry>
        </collision>
    </link>
    <link name="ak70-10-v1_2">
        <inertial>
            <origin xyz="0.0008327123573129318 7.146546048771185e-05 -0.01790093202006832" rpy="0.0 -0.0 0.0" />
            <mass value="2.1429063401431327" />
            <inertia ixx="0.0013533717650108454" iyy="0.0013525905951489493" izz="0.0019425719918165357" ixy="3.220536393237654e-06" iyz="3.49799997046991e-06" ixz="-2.1729090419244698e-05" />
        </inertial>
        <visual name="ak70-10-v1_2_visual">
            <origin xyz="0.0018629057736697058 -1.9984014443252818e-14 -0.04381050376250973" rpy="1.5707963267949068 1.5283000565118277 1.7143410555958367e-14" />
            <geometry>
                <mesh filename="meshes/ak70-10-v1_2.stl" scale="0.001 0.001 0.001" />
            </geometry>
        </visual>
        <collision name="ak70-10-v1_2_collision">
            <origin xyz="0.0018629057736697058 -1.9984014443252818e-14 -0.04381050376250973" rpy="1.5707963267949068 1.5283000565118277 1.7143410555958367e-14" />
            <geometry>
                <mesh filename="meshes/ak70-10-v1_2.stl" scale="0.001 0.001 0.001" />
            </geometry>
        </collision>
    </link>
    <joint name="ak60-6v1-1-v1_회전-1" type="continuous">
        <origin xyz="-0.006440049999999999 -0.0002738400000000008 0.02827455999999998" rpy="-3.141592653589793 -1.5707963267948966 0" />
        <parent link="ak60-6v1-1-v1" />
        <child link="Component11" />
        <axis xyz="-0.9749849999999999 -0.009442999999999993 0.22207099999999996" />
    </joint>
    <joint name="base_link_강체-4" type="fixed">
        <origin xyz="0.0 0.0 0.023" rpy="0.0 -0.0 0.0" />
        <parent link="base_link" />
        <child link="ak70-10-v1_1" />
    </joint>
    <joint name="ak70-10-v1_1_회전-5" type="continuous">
        <origin xyz="0.0 0.0 0.03905" rpy="-3.141592653589793 -1.5707963267948966 0" />
        <parent link="ak70-10-v1_1" />
        <child link="Component2" />
        <axis xyz="-1.0 -0.0 -7.888609052210118e-31" />
    </joint>
    <joint name="Component2_강체-6" type="fixed">
        <origin xyz="0.02 0.0 1.5777218104420236e-32" rpy="-3.141592653589793 -1.5707963267948966 0" />
        <parent link="Component2" />
        <child link="Component3" />
    </joint>
    <joint name="Component3_강체-7" type="fixed">
        <origin xyz="-0.0138827 -0.02659456 0.01800000000000001" rpy="3.141592653589793 -0.0 -1.6001510861891693e-31" />
        <parent link="Component3" />
        <child link="Component4" />
    </joint>
    <joint name="Component4_강체-8" type="fixed">
        <origin xyz="0.01319128 -0.042854869999999996 -0.056999999999999995" rpy="1.5707963267948966 -0.0 3.2178910748521876e-30" />
        <parent link="Component4" />
        <child link="ak70-10-v1_2" />
    </joint>
    <joint name="ak70-10-v1_2_회전-9" type="continuous">
        <origin xyz="-0.00027189000000000005 0.0 0.0063941300000000005" rpy="-1.5707963267948966 6.902532920683855e-31 -1.5707963267948966" />
        <parent link="ak70-10-v1_2" />
        <child link="Component5" />
        <axis xyz="7.881485638235972e-31 0.9990969999999999 0.042483" />
    </joint>
    <joint name="ak70-10-v1_2_강체-10" type="fixed">
        <origin xyz="0.0013870900000000001 0.0 -0.03262062" rpy="1.5707963267948966 6.902532920683855e-31 -1.5707963267948966" />
        <parent link="ak70-10-v1_2" />
        <child link="Component6" />
    </joint>
    <joint name="Component5_강체-11" type="fixed">
        <origin xyz="0.03168701 -0.024670539999999998 -0.00827939" rpy="1.5707963267948966 -1.5707963267948966 0" />
        <parent link="Component5" />
        <child link="Component7" />
    </joint>
    <joint name="Component7_강체-12" type="fixed">
        <origin xyz="0.002351049999999999 0.012187310000000019 0.010109000000000003" rpy="-7.227596320303442e-19 -6.261554580234533e-18 0.0" />
        <parent link="Component7" />
        <child link="Component8_1" />
    </joint>
    <joint name="ak60-6v1-1-v1_강체-13" type="fixed">
        <origin xyz="-0.0061069500000000025 -0.000259680000000001 0.02681207999999998" rpy="-3.141592653589793 -1.5707963267948966 0" />
        <parent link="ak60-6v1-1-v1" />
        <child link="Component10" />
    </joint>
    <joint name="Component9_강체-16" type="fixed">
        <origin xyz="0.014937280000000018 0.010437270000000005 0.041402789999999995" rpy="-1.5707963267948966 -2.1956751568497123e-18 2.775557561562892e-17" />
        <parent link="Component9" />
        <child link="ak60-6v1-1-v1" />
    </joint>
    <joint name="Component8_1_강체-17" type="fixed">
        <origin xyz="-0.03080084 -0.06853650000000001 -0.009316940000000003" rpy="3.141592653589793 1.700735212931283e-18 -2.7755575615628914e-17" />
        <parent link="Component8_1" />
        <child link="Component9" />
    </joint>
    <joint name="Component9_강체-19" type="fixed">
        <origin xyz="0.003568610000000043 0.0 0.08392416000000001" rpy="2.3777449427013474e-18 -2.1956751568497123e-18 2.775557561562892e-17" />
        <parent link="Component9" />
        <child link="Component8_2" />
    </joint>
</robot>