<?xml version='1.0' encoding='utf-8'?>
<robot name="sfbot">
    <link name="base_link">
        <inertial>
            <origin xyz="0.0013386396517363875 -0.0011242493747386578 0.009051092998347913" rpy="0.0 0.0 0.0" />
            <mass value="3.888884702652834" />
            <inertia ixx="0.010759968313061485" iyy="0.010736881042533725" izz="0.020894462545599256" ixy="0.00021664303992281595" iyz="0.00020888253586269707" ixz="-0.00017260000031820458" />
        </inertial>
        <visual name="base_link_visual">
            <origin xyz="0.0 0.0 0.0" rpy="0.0 0.0 0.0" />
            <geometry>
                <mesh filename="meshes/base_link.stl" scale="0.001 0.001 0.001" />
            </geometry>
        </visual>
        <collision name="base_link_collision">
            <origin xyz="0.0 0.0 0.0" rpy="0.0 0.0 0.0" />
            <geometry>
                <mesh filename="meshes/base_link.stl" scale="0.001 0.001 0.001" />
            </geometry>
        </collision>
    </link>
    <link name="Component2">
        <inertial>
            <origin xyz="0.010945074522193012 -9.160869287532606e-05 8.62984535093997e-05" rpy="0.0 -0.0 0.0" />
            <mass value="1.0016922735671667" />
            <inertia ixx="0.001126039535837206" iyy="0.0005943954489626311" izz="0.000594737618088737" ixy="-5.921872837896801e-07" iyz="2.862941124099891e-06" ixz="5.578682845693662e-07" />
        </inertial>
        <visual name="Component2_visual">
            <origin xyz="-0.06300000093877291 -1.6370404527291505e-33 -5.3241520732561644e-18" rpy="-1.5707963267948963 -0.842827213480541 -1.570796326794897" />
            <geometry>
                <mesh filename="meshes/Component2.stl" scale="0.001 0.001 0.001" />
            </geometry>
        </visual>
        <collision name="Component2_collision">
            <origin xyz="-0.06300000093877291 -1.6370404527291505e-33 -5.3241520732561644e-18" rpy="-1.5707963267948963 -0.842827213480541 -1.570796326794897" />
            <geometry>
                <mesh filename="meshes/Component2.stl" scale="0.001 0.001 0.001" />
            </geometry>
        </collision>
    </link>
    <link name="Component3">
        <inertial>
            <origin xyz="0.0015968025180715614 -0.0007068663528580886 0.008375687022008726" rpy="0.0 -0.0 -4.673574673337829e-96" />
            <mass value="0.8807950300955173" />
            <inertia ixx="0.000497172389036897" iyy="0.0005454437322308424" izz="0.0009807519381805896" ixy="1.832401478465408e-05" iyz="8.911075345348467e-06" ixz="-2.0131230059733065e-05" />
        </inertial>
        <visual name="Component3_visual">
            <origin xyz="-1.5680591166870976e-17 -1.4980581733704105e-17 -0.08500000126659883" rpy="-1.8366197940234355e-16 1.5800624615796233e-16 0.7279691133143557" />
            <geometry>
                <mesh filename="meshes/Component3.stl" scale="0.001 0.001 0.001" />
            </geometry>
        </visual>
        <collision name="Component3_collision">
            <origin xyz="-1.5680591166870976e-17 -1.4980581733704105e-17 -0.08500000126659883" rpy="-1.8366197940234355e-16 1.5800624615796233e-16 0.7279691133143557" />
            <geometry>
                <mesh filename="meshes/Component3.stl" scale="0.001 0.001 0.001" />
            </geometry>
        </collision>
    </link>
    <link name="Component4">
        <inertial>
            <origin xyz="0.0021084174599809804 -0.002365641246588215 0.019811113493133695" rpy="0.0 -0.0 -3.038581678643137e-64" />
            <mass value="0.6184682868789885" />
            <inertia ixx="0.0006473603863162405" iyy="0.0006742126257851444" izz="0.0005760836245137029" ixy="-0.00011637861748748493" iyz="5.697925210444991e-05" ixz="-5.078371463367915e-05" />
        </inertial>
        <visual name="Component4_visual">
            <origin xyz="-1.2612327294524078e-17 -1.435526505732049e-17 -0.10326725730081637" rpy="-8.064064060156788e-17 5.436150775560778e-16 0.7279691133143555" />
            <geometry>
                <mesh filename="meshes/Component4.stl" scale="0.001 0.001 0.001" />
            </geometry>
        </visual>
        <collision name="Component4_collision">
            <origin xyz="-1.2612327294524078e-17 -1.435526505732049e-17 -0.10326725730081637" rpy="-8.064064060156788e-17 5.436150775560778e-16 0.7279691133143555" />
            <geometry>
                <mesh filename="meshes/Component4.stl" scale="0.001 0.001 0.001" />
            </geometry>
        </collision>
    </link>
    <link name="Component5">
        <inertial>
            <origin xyz="-0.0002313195805737145 0.01098525840071326 0.010748581192048957" rpy="0.0 -0.0 0.0" />
            <mass value="0.6082106863628858" />
            <inertia ixx="0.00024215569443510423" iyy="0.000330925878407504" izz="0.00030578471297590913" ixy="-3.403310431142944e-06" iyz="9.132701252404982e-05" ixz="4.801252736232574e-06" />
        </inertial>
        <visual name="Component5_visual">
            <origin xyz="-0.13142613255344568 -0.0733364614208679 0.04470946717118674" rpy="-2.1073950338533427 -0.6854071547486255 -0.8164783674652264" />
            <geometry>
                <mesh filename="meshes/Component5.stl" scale="0.001 0.001 0.001" />
            </geometry>
        </visual>
        <collision name="Component5_collision">
            <origin xyz="-0.13142613255344568 -0.0733364614208679 0.04470946717118674" rpy="-2.1073950338533427 -0.6854071547486255 -0.8164783674652264" />
            <geometry>
                <mesh filename="meshes/Component5.stl" scale="0.001 0.001 0.001" />
            </geometry>
        </collision>
    </link>
    <link name="Component6">
        <inertial>
            <origin xyz="-0.002832919946578922 0.010673732921733677 0.009504783830583983" rpy="0.0 -0.0 0.0" />
            <mass value="0.8292297988354185" />
            <inertia ixx="0.0005834388068200741" iyy="0.0007189412638555666" izz="0.0006611514683360561" ixy="-1.1010921434279671e-05" iyz="0.0002501836636928443" ixz="-9.508628468114441e-06" />
        </inertial>
        <visual name="Component6_visual">
            <origin xyz="-0.1602672573008176 -3.4051647057609104e-10 -4.096731078817583e-09" rpy="1.5707963267948988 0.8428272134805398 1.5707963267949008" />
            <geometry>
                <mesh filename="meshes/Component6.stl" scale="0.001 0.001 0.001" />
            </geometry>
        </visual>
        <collision name="Component6_collision">
            <origin xyz="-0.1602672573008176 -3.4051647057609104e-10 -4.096731078817583e-09" rpy="1.5707963267948988 0.8428272134805398 1.5707963267949008" />
            <geometry>
                <mesh filename="meshes/Component6.stl" scale="0.001 0.001 0.001" />
            </geometry>
        </collision>
    </link>
    <link name="Component7">
        <inertial>
            <origin xyz="0.00330339877798576 -1.9877433032888802e-14 -0.003706411490582018" rpy="-4.81482486096809e-35 -0.0 4.276423536147513e-50" />
            <mass value="0.3722794963916967" />
            <inertia ixx="0.00021526300858660207" iyy="0.00015112472607940654" izz="0.0002318671691311085" ixy="-2.754307219458277e-15" iyz="-2.3236631164745118e-15" ixz="-7.196305734395455e-05" />
        </inertial>
        <visual name="Component7_visual">
            <origin xyz="0.030975234271780245 0.13589229347178253 0.09294306846118146" rpy="2.0121993223942147 -0.5994172531861878 -0.6972031176901101" />
            <geometry>
                <mesh filename="meshes/Component7.stl" scale="0.001 0.001 0.001" />
            </geometry>
        </visual>
        <collision name="Component7_collision">
            <origin xyz="0.030975234271780245 0.13589229347178253 0.09294306846118146" rpy="2.0121993223942147 -0.5994172531861878 -0.6972031176901101" />
            <geometry>
                <mesh filename="meshes/Component7.stl" scale="0.001 0.001 0.001" />
            </geometry>
        </collision>
    </link>
    <link name="Component8_1">
        <inertial>
            <origin xyz="-0.009353527345711342 -0.02572134414379704 -0.013675551530943438" rpy="0.0 1.951722043804704e-33 0.0" />
            <mass value="0.668762166036501" />
            <inertia ixx="0.0008411658021223074" iyy="0.0004009458121184724" izz="0.0009080271804395336" ixy="-0.0002301415316596132" iyz="-0.00017989939049010438" ixz="-0.000187074653225834" />
        </inertial>
        <visual name="Component8_1_visual">
            <origin xyz="0.007915274147031375 0.016958209999975438 0.007054620400172471" rpy="2.0121993223942147 -0.5994172531861813 -0.697203117690107" />
            <geometry>
                <mesh filename="meshes/Component8_1.stl" scale="0.001 0.001 0.001" />
            </geometry>
        </visual>
        <collision name="Component8_1_collision">
            <origin xyz="0.007915274147031375 0.016958209999975438 0.007054620400172471" rpy="2.0121993223942147 -0.5994172531861813 -0.697203117690107" />
            <geometry>
                <mesh filename="meshes/Component8_1.stl" scale="0.001 0.001 0.001" />
            </geometry>
        </collision>
    </link>
    <link name="Component8_2">
        <inertial>
            <origin xyz="-0.00038592097122751133 -0.04484655585619855 -0.015711388569849806" rpy="0.0 -0.0 0.0" />
            <mass value="0.668762166036501" />
            <inertia ixx="0.000864551870715706" iyy="0.00040094581211848313" izz="0.0008846411118463432" ixy="0.0002050895806490812" iyz="-0.00020800764217344164" ixz="0.0001897726072299753" />
        </inertial>
        <visual name="Component8_2_visual">
            <origin xyz="0.02218676454501606 -0.087526109999977 -0.0304906105342731" rpy="1.1293933311955886 -0.5994172531861808 -2.4443895358996865" />
            <geometry>
                <mesh filename="meshes/Component8_2.stl" scale="0.001 0.001 0.001" />
            </geometry>
        </visual>
        <collision name="Component8_2_collision">
            <origin xyz="0.02218676454501606 -0.087526109999977 -0.0304906105342731" rpy="1.1293933311955886 -0.5994172531861808 -2.4443895358996865" />
            <geometry>
                <mesh filename="meshes/Component8_2.stl" scale="0.001 0.001 0.001" />
            </geometry>
        </collision>
    </link>
    <link name="Component9">
        <inertial>
            <origin xyz="-0.03860868860384741 -0.016898418878394283 -0.02184821992979015" rpy="0.0 -4.8206843164870855e-34 0.0" />
            <mass value="0.6867109263567744" />
            <inertia ixx="0.0006726115829582963" iyy="0.0009691880820986687" izz="0.0006439142007981723" ixy="-0.00014524893892977993" iyz="0.00012945935015369888" ixz="-0.00012418645568407376" />
        </inertial>
        <visual name="Component9_visual">
            <origin xyz="-0.040407410019029595 -0.001887147194137242 -0.020246727204803125" rpy="-1.1293933311955748 0.599417253186201 0.6972031176901189" />
            <geometry>
                <mesh filename="meshes/Component9.stl" scale="0.001 0.001 0.001" />
            </geometry>
        </visual>
        <collision name="Component9_collision">
            <origin xyz="-0.040407410019029595 -0.001887147194137242 -0.020246727204803125" rpy="-1.1293933311955748 0.599417253186201 0.6972031176901189" />
            <geometry>
                <mesh filename="meshes/Component9.stl" scale="0.001 0.001 0.001" />
            </geometry>
        </collision>
    </link>
    <link name="ak60-6v1-1-v1">
        <inertial>
            <origin xyz="-0.0044358012160089985 0.003953485051277621 -0.009127301065465759" rpy="0.0 -0.0 0.0" />
            <mass value="1.2585201056414106" />
            <inertia ixx="0.0006289699116548281" iyy="0.0006178380089657547" izz="0.0008013663840159486" ixy="-4.824608563589667e-05" iyz="-9.451105198622543e-05" ixz="0.00010604125941979975" />
        </inertial>
        <visual name="ak60-6v1-1-v1_visual">
            <origin xyz="0.004155516302009739 -0.0037036708616082635 0.008903057653659624" rpy="1.570796326794908 -1.0120314028019524 -0.7279691133143787" />
            <geometry>
                <mesh filename="meshes/ak60-6v1-1-v1.stl" scale="0.001 0.001 0.001" />
            </geometry>
        </visual>
        <collision name="ak60-6v1-1-v1_collision">
            <origin xyz="0.004155516302009739 -0.0037036708616082635 0.008903057653659624" rpy="1.570796326794908 -1.0120314028019524 -0.7279691133143787" />
            <geometry>
                <mesh filename="meshes/ak60-6v1-1-v1.stl" scale="0.001 0.001 0.001" />
            </geometry>
        </collision>
    </link>
    <link name="Component10">
        <inertial>
            <origin xyz="0.0034224477594011304 0.0022600688394708345 0.0017471818283731988" rpy="0.0 -0.0 0.0" />
            <mass value="0.13156890942165747" />
            <inertia ixx="0.00012464823151851393" iyy="8.518040657010809e-05" izz="8.103059661961239e-05" ixy="1.7690136571782412e-05" iyz="-1.3494937321924455e-05" ixz="-2.6224095454487876e-05" />
        </inertial>
        <visual name="Component10_visual">
            <origin xyz="2.105218328551928e-09 4.68034455636257e-10 4.854155211120315e-09" rpy="-2.1073950338533614 -0.6854071547486059 -0.8164783674652344" />
            <geometry>
                <mesh filename="meshes/Component10.stl" scale="0.001 0.001 0.001" />
            </geometry>
        </visual>
        <collision name="Component10_collision">
            <origin xyz="2.105218328551928e-09 4.68034455636257e-10 4.854155211120315e-09" rpy="-2.1073950338533614 -0.6854071547486059 -0.8164783674652344" />
            <geometry>
                <mesh filename="meshes/Component10.stl" scale="0.001 0.001 0.001" />
            </geometry>
        </collision>
    </link>
    <link name="Component11">
        <inertial>
            <origin xyz="0.008985403830917704 0.0037731961670967886 -0.004142839379512955" rpy="0.0 -0.0 0.0" />
            <mass value="0.3456856671384452" />
            <inertia ixx="0.00013399840473538835" iyy="9.435318955571673e-05" izz="9.631166432266802e-05" ixy="1.98470746546565e-05" iyz="-9.521266281541583e-06" ixz="-2.2283922566711932e-05" />
        </inertial>
        <visual name="Component11_visual">
            <origin xyz="-2.704455717150722e-09 -3.540555049141858e-09 -5.936541036533071e-11" rpy="2.254811437509842 -0.8940018879754432 1.39882407164249" />
            <geometry>
                <mesh filename="meshes/Component11.stl" scale="0.001 0.001 0.001" />
            </geometry>
        </visual>
        <collision name="Component11_collision">
            <origin xyz="-2.704455717150722e-09 -3.540555049141858e-09 -5.936541036533071e-11" rpy="2.254811437509842 -0.8940018879754432 1.39882407164249" />
            <geometry>
                <mesh filename="meshes/Component11.stl" scale="0.001 0.001 0.001" />
            </geometry>
        </collision>
    </link>
    <link name="ak70-10-v1_1">
        <inertial>
            <origin xyz="-7.146546050767142e-05 7.146546059160692e-05 0.014729945989910705" rpy="0.0 -0.0 0.0" />
            <mass value="2.1429063401431327" />
            <inertia ixx="0.0013525905951485492" iyy="0.0013525905928285925" izz="0.0019433531639984443" ixy="-3.3662360080575286e-06" iyz="3.358022274098476e-06" ixz="-3.358022273844245e-06" />
        </inertial>
        <visual name="ak70-10-v1_1_visual">
            <origin xyz="-4.551914400963142e-17 0.0 -0.011199999999999993" rpy="-0.0 1.5707963267948926 0" />
            <geometry>
                <mesh filename="meshes/ak70-10-v1_1.stl" scale="0.001 0.001 0.001" />
            </geometry>
        </visual>
        <collision name="ak70-10-v1_1_collision">
            <origin xyz="-4.551914400963142e-17 0.0 -0.011199999999999993" rpy="-0.0 1.5707963267948926 0" />
            <geometry>
                <mesh filename="meshes/ak70-10-v1_1.stl" scale="0.001 0.001 0.001" />
            </geometry>
        </collision>
    </link>
    <link name="ak70-10-v1_2">
        <inertial>
            <origin xyz="-0.011976605131056566 7.146546048318214e-05 0.013330324409629685" rpy="0.0 6.077163357286271e-64 0.0" />
            <mass value="2.1429063401431327" />
            <inertia ixx="0.0016107835956650149" iyy="0.0013525905951491562" izz="0.001685160161162623" ixy="-2.787101853048645e-07" iyz="-4.7465965792571575e-06" ixz="-0.00029305018651013047" />
        </inertial>
        <visual name="ak70-10-v1_2_visual">
            <origin xyz="-0.029175870738694876 -2.4567015088905464e-14 0.03273528431450385" rpy="-1.5707963267948946 -0.8428272134805325 3.141592653589793" />
            <geometry>
                <mesh filename="meshes/ak70-10-v1_2.stl" scale="0.001 0.001 0.001" />
            </geometry>
        </visual>
        <collision name="ak70-10-v1_2_collision">
            <origin xyz="-0.029175870738694876 -2.4567015088905464e-14 0.03273528431450385" rpy="-1.5707963267948946 -0.8428272134805325 3.141592653589793" />
            <geometry>
                <mesh filename="meshes/ak70-10-v1_2.stl" scale="0.001 0.001 0.001" />
            </geometry>
        </collision>
    </link>
    <joint name="base_link_fix-1" type="fixed">
        <origin xyz="0.0 0.0 0.023" rpy="0.0 -0.0 0.0" />
        <parent link="base_link" />
        <child link="ak70-10-v1_1" />
    </joint>
    <joint name="ak70-10-v1_1_con-2" type="continuous">
        <origin xyz="0.0 0.0 0.03905" rpy="-3.141592653589793 -1.5707963267948966 0" />
        <parent link="ak70-10-v1_1" />
        <child link="Component2" />
        <axis xyz="-1.0 -4.75865530677569e-32 -0.0" />
    </joint>
    <joint name="Component2_fix-3" type="fixed">
        <origin xyz="0.02 0.0 0.0" rpy="-3.141592653589793 -1.5707963267948966 0" />
        <parent link="Component2" />
        <child link="Component3" />
    </joint>
    <joint name="Component3_fix-4" type="fixed">
        <origin xyz="2.218671295934097e-34 3.4124888101640537e-66 0.01800000000000001" rpy="-3.0814879110195774e-32 2.736911063134409e-48 -5.551115123125782e-17" />
        <parent link="Component3" />
        <child link="Component4" />
    </joint>
    <joint name="Component4_fix-5" type="fixed">
        <origin xyz="0.01082865 -0.012149730000000001 0.056999999999999995" rpy="-1.5707963267948966 7.395570986446986e-32 5.5511151231257815e-17" />
        <parent link="Component4" />
        <child link="ak70-10-v1_2" />
    </joint>
    <joint name="ak70-10-v1_2_fix-6" type="fixed">
        <origin xyz="-0.0217239 0.0 0.024374180000000002" rpy="1.5707963267948966 3.8826747678846675e-31 -1.5707963267948966" />
        <parent link="ak70-10-v1_2" />
        <child link="Component6" />
    </joint>
    <joint name="ak70-10-v1_2_con-7" type="continuous">
        <origin xyz="0.00425821 0.0 -0.004777709999999999" rpy="-1.5707963267948966 3.8826747678846675e-31 -1.5707963267948966" />
        <parent link="ak70-10-v1_2" />
        <child link="Component5" />
        <axis xyz="-2.9445298249596316e-31 -0.746527 -0.665355" />
    </joint>
    <joint name="Component5_fix-8" type="fixed">
        <origin xyz="0.0 0.018663179999999998 0.01663388" rpy="1.5707963267948966 -1.5707963267948966 0" />
        <parent link="Component5" />
        <child link="Component7" />
    </joint>
    <joint name="Component7_fix-9" type="fixed">
        <origin xyz="-0.001261729999999992 -0.016958210000000005 -0.014519890000000002" rpy="7.557866748226106e-17 -6.518246424920506e-18 -5.5511151231257815e-17" />
        <parent link="Component7" />
        <child link="Component8_1" />
    </joint>
    <joint name="Component8_1_fix-10" type="fixed">
        <origin xyz="-0.02491717000000001 -0.07056790000000003 -0.011491559999999987" rpy="3.141592653589793 2.1919201952020058e-17 0.0" />
        <parent link="Component8_1" />
        <child link="Component9" />
    </joint>
    <joint name="Component9_fix-11" type="fixed">
        <origin xyz="-0.05588981000000004 0.0 -0.06270829" rpy="-1.611776653068683e-17 -6.996850281877054e-18 -5.551115123125783e-17" />
        <parent link="Component9" />
        <child link="Component8_2" />
    </joint>
    <joint name="Component9_fix-12" type="fixed">
        <origin xyz="-0.040407410000000005 -0.0018871499999999842 -0.02024673" rpy="1.5707963267948946 -6.996850281877054e-18 -5.551115123125783e-17" />
        <parent link="Component9" />
        <child link="ak60-6v1-1-v1" />
    </joint>
    <joint name="ak60-6v1-1-v1_fix-13" type="fixed">
        <origin xyz="-0.01088349999999978 0.009700100000000047 -0.023317539999999966" rpy="-1.1973097379898163e-16 1.5707963267948872 0" />
        <parent link="ak60-6v1-1-v1" />
        <child link="Component10" />
    </joint>
    <joint name="ak60-6v1-1-v1_con-14" type="continuous">
        <origin xyz="-0.011477139999999775 0.010229200000000046 -0.024589409999999957" rpy="-1.1973097379898163e-16 1.5707963267948872 0" />
        <parent link="ak60-6v1-1-v1" />
        <child link="Component11" />
        <axis xyz="-0.8479109999999997 -0.35273099999999996 0.3957629999999999" />
    </joint>
</robot>