<?xml version='1.0' encoding='utf-8'?>
<robot name="sfbot">
    <link name="base_link">
        <inertial>
            <origin xyz="0.0013386396517363875 -0.0011242493747386578 0.009051092998347913" rpy="0.0 0.0 0.0" />
            <mass value="3.888884702652834" />
            <inertia ixx="0.010759968313061485" iyy="0.010736881042533725" izz="0.020894462545599256" ixy="0.00021664303992281595" iyz="0.00020888253586269707" ixz="-0.00017260000031820458" />
        </inertial>
        <visual name="base_link_visual">
            <origin xyz="0.0 0.0 0.0" rpy="0.0 0.0 0.0" />
            <geometry>
                <mesh filename="meshes/base_link.stl" scale="0.001 0.001 0.001" />
            </geometry>
        </visual>
        <collision name="base_link_collision">
            <origin xyz="0.0 0.0 0.0" rpy="0.0 0.0 0.0" />
            <geometry>
                <mesh filename="meshes/base_link.stl" scale="0.001 0.001 0.001" />
            </geometry>
        </collision>
    </link>
    <link name="구성요소2">
        <inertial>
            <origin xyz="0.010945074522191733 -0.00010534873925930989 -6.88565089507307e-05" rpy="0.0 -0.0 0.0" />
            <mass value="1.0016922735671667" />
            <inertia ixx="0.0011260395358369433" iyy="0.0005934154778176413" izz="0.0005957175892346523" ixy="-6.810150746576772e-07" iyz="-2.626932158181823e-06" ixz="-4.451081555066191e-07" />
        </inertial>
        <visual name="구성요소2_visual">
            <origin xyz="-0.06300000093876555 -4.248888595462965e-19 -7.050525325149703e-17" rpy="-1.5707963267948923 0.4916370591132493 -1.5707963267948946" />
            <geometry>
                <mesh filename="meshes/구성요소2.stl" scale="0.001 0.001 0.001" />
            </geometry>
        </visual>
        <collision name="구성요소2_collision">
            <origin xyz="-0.06300000093876555 -4.248888595462965e-19 -7.050525325149703e-17" rpy="-1.5707963267948923 0.4916370591132493 -1.5707963267948946" />
            <geometry>
                <mesh filename="meshes/구성요소2.stl" scale="0.001 0.001 0.001" />
            </geometry>
        </collision>
    </link>
    <link name="구성요소3">
        <inertial>
            <origin xyz="0.0010610903143045798 0.0013869122781963795 0.008375687022005193" rpy="0.0 -0.0 -1.555753819465285e-61" />
            <mass value="0.8807950300955173" />
            <inertia ixx="0.0005344552737856605" iyy="0.0005081608474835986" izz="0.000980751938180358" ixy="-2.7302947599626452e-05" iyz="-1.7485225359674623e-05" ixz="-1.3376867407941974e-05" />
        </inertial>
        <visual name="구성요소3_visual">
            <origin xyz="-1.9116652705264415e-16 1.930053339371796e-16 -0.08500000126659131" rpy="3.8596544065459926e-15 -4.1071080104835324e-15 2.062433385908146" />
            <geometry>
                <mesh filename="meshes/구성요소3.stl" scale="0.001 0.001 0.001" />
            </geometry>
        </visual>
        <collision name="구성요소3_collision">
            <origin xyz="-1.9116652705264415e-16 1.930053339371796e-16 -0.08500000126659131" rpy="3.8596544065459926e-15 -4.1071080104835324e-15 2.062433385908146" />
            <geometry>
                <mesh filename="meshes/구성요소3.stl" scale="0.001 0.001 0.001" />
            </geometry>
        </collision>
    </link>
    <link name="구성요소4">
        <inertial>
            <origin xyz="0.03277822538372141 -0.0005372334212360475 -0.019811113493126555" rpy="0.0 8.758115402030109e-47 6.223015277861143e-61" />
            <mass value="0.6184682868789885" />
            <inertia ixx="0.0007257230859734098" iyy="0.0005958499261296943" izz="0.000576083624513573" ixy="-9.750632742278296e-05" iyz="-3.6031075239847225e-05" ixz="6.72858265865581e-05" />
        </inertial>
        <visual name="구성요소4_visual">
            <origin xyz="0.029984679999998848 0.0009586899999998447 0.1032672573008095" rpy="-3.141592653589782 8.080811996581908e-15 -2.0624333859081463" />
            <geometry>
                <mesh filename="meshes/구성요소4.stl" scale="0.001 0.001 0.001" />
            </geometry>
        </visual>
        <collision name="구성요소4_collision">
            <origin xyz="0.029984679999998848 0.0009586899999998447 0.1032672573008095" rpy="-3.141592653589782 8.080811996581908e-15 -2.0624333859081463" />
            <geometry>
                <mesh filename="meshes/구성요소4.stl" scale="0.001 0.001 0.001" />
            </geometry>
        </collision>
    </link>
    <link name="구성요소5">
        <inertial>
            <origin xyz="-0.0005012726000584423 -0.007740981794083404 0.013269791084441063" rpy="0.0 -0.0 0.0" />
            <mass value="0.6082106863628858" />
            <inertia ixx="0.0002351984697331914" iyy="0.000271357213411063" izz="0.0003723106026756566" ixy="-9.346144146587815e-06" iyz="-7.293865585819844e-05" ixz="-3.397455881401241e-06" />
        </inertial>
        <visual name="구성요소5_visual">
            <origin xyz="-0.1534522067211019 -0.007460337634424112 -0.03235373520956503" rpy="-1.4954521335481799 0.486297355749836 -1.4106597868084407" />
            <geometry>
                <mesh filename="meshes/구성요소5.stl" scale="0.001 0.001 0.001" />
            </geometry>
        </visual>
        <collision name="구성요소5_collision">
            <origin xyz="-0.1534522067211019 -0.007460337634424112 -0.03235373520956503" rpy="-1.4954521335481799 0.486297355749836 -1.4106597868084407" />
            <geometry>
                <mesh filename="meshes/구성요소5.stl" scale="0.001 0.001 0.001" />
            </geometry>
        </collision>
    </link>
    <link name="구성요소6">
        <inertial>
            <origin xyz="-0.002832919946589545 -0.006741460801853347 0.01260247705552177" rpy="0.0 -0.0 0.0" />
            <mass value="0.8292297988354185" />
            <inertia ixx="0.0005834388068199187" iyy="0.0005504209535344869" izz="0.0008296717786611292" ixy="6.666242608004007e-06" iyz="-0.0002095984848748207" ixz="-1.2931187712956604e-05" />
        </inertial>
        <visual name="구성요소6_visual">
            <origin xyz="-0.16026725730080962 -3.3418328637679907e-09 4.019980184288841e-09" rpy="1.5707963267949123 -0.4916370591132429 1.570796326794888" />
            <geometry>
                <mesh filename="meshes/구성요소6.stl" scale="0.001 0.001 0.001" />
            </geometry>
        </visual>
        <collision name="구성요소6_collision">
            <origin xyz="-0.16026725730080962 -3.3418328637679907e-09 4.019980184288841e-09" rpy="1.5707963267949123 -0.4916370591132429 1.570796326794888" />
            <geometry>
                <mesh filename="meshes/구성요소6.stl" scale="0.001 0.001 0.001" />
            </geometry>
        </collision>
    </link>
    <link name="구성요소7">
        <inertial>
            <origin xyz="0.0022140839712372086 0.03217545999998864 0.006382586951279614" rpy="-1.5407439555097887e-33 -1.2052048474587312e-32 0.0" />
            <mass value="0.3722794963916967" />
            <inertia ixx="0.0002637188123312922" iyy="0.00015112472607729718" izz="0.00018341136538885087" ixy="5.269247859429115e-16" iyz="-9.673247430498497e-16" ixz="6.029332177240523e-05" />
        </inertial>
        <visual name="구성요소7_visual">
            <origin xyz="-0.0558261296362406 0.19084232407406032 0.0009302728675083039" rpy="-1.828204495888397 -1.0608242926663185 -2.8486430548058324" />
            <geometry>
                <mesh filename="meshes/구성요소7.stl" scale="0.001 0.001 0.001" />
            </geometry>
        </visual>
        <collision name="구성요소7_collision">
            <origin xyz="-0.0558261296362406 0.19084232407406032 0.0009302728675083039" rpy="-1.828204495888397 -1.0608242926663185 -2.8486430548058324" />
            <geometry>
                <mesh filename="meshes/구성요소7.stl" scale="0.001 0.001 0.001" />
            </geometry>
        </collision>
    </link>
    <link name="구성요소8_1">
        <inertial>
            <origin xyz="0.005532368881680805 -0.030032060326782073 -0.0018882210545547952" rpy="0.0 6.162975822039156e-33 0.0" />
            <mass value="0.668762166036501" />
            <inertia ixx="0.0010200817152389813" iyy="0.00023157548062721368" izz="0.000898481598814289" ixy="2.3346197968730452e-05" iyz="-9.016086767014376e-05" ixz="8.564854710013023e-05" />
        </inertial>
        <visual name="구성요소8_1_visual">
            <origin xyz="-0.0013309346240632004 0.019800279999987538 0.0024854270503780595" rpy="-1.8282044958883956 -1.06082429266632 -2.8486430548058315" />
            <geometry>
                <mesh filename="meshes/구성요소8_1.stl" scale="0.001 0.001 0.001" />
            </geometry>
        </visual>
        <collision name="구성요소8_1_collision">
            <origin xyz="-0.0013309346240632004 0.019800279999987538 0.0024854270503780595" rpy="-1.8282044958883956 -1.06082429266632 -2.8486430548058315" />
            <geometry>
                <mesh filename="meshes/구성요소8_1.stl" scale="0.001 0.001 0.001" />
            </geometry>
        </collision>
    </link>
    <link name="구성요소9">
        <inertial>
            <origin xyz="-0.02762615404184598 -0.009657915195907378 0.03737716170652959" rpy="0.0 6.259671523940261e-33 0.0" />
            <mass value="0.6867109263567744" />
            <inertia ixx="0.0005636250001413085" iyy="0.0010828336400132339" izz="0.0006392552257005327" ixy="2.9146628363436193e-05" iyz="5.444266156357389e-05" ixz="5.674394133588024e-05" />
        </inertial>
        <visual name="구성요소9_visual">
            <origin xyz="-0.029460130885617285 0.0050411766971200575 0.03395492826723322" rpy="1.3133881577013726 1.0608242926662954 2.848643054805845" />
            <geometry>
                <mesh filename="meshes/구성요소9.stl" scale="0.001 0.001 0.001" />
            </geometry>
        </visual>
        <collision name="구성요소9_collision">
            <origin xyz="-0.029460130885617285 0.0050411766971200575 0.03395492826723322" rpy="1.3133881577013726 1.0608242926662954 2.848643054805845" />
            <geometry>
                <mesh filename="meshes/구성요소9.stl" scale="0.001 0.001 0.001" />
            </geometry>
        </collision>
    </link>
    <link name="ak60-6v1-1-v1">
        <inertial>
            <origin xyz="0.000817859947299997 -0.0015273032896083293 0.010752316016905112" rpy="0.0 -0.0 0.0" />
            <mass value="1.2585201056414106" />
            <inertia ixx="0.0005777626851051767" iyy="0.0005850376445638295" izz="0.0008853739749672641" ixy="-5.461902827369391e-06" iyz="-4.181182390359259e-05" ixz="2.238993038224285e-05" />
        </inertial>
        <visual name="ak60-6v1-1-v1_visual">
            <origin xyz="-0.0006987390328387133 0.0013048524342867353 -0.010395152635370693" rpy="-1.5707963267949223 1.4293577073673651 2.062433385908139" />
            <geometry>
                <mesh filename="meshes/ak60-6v1-1-v1.stl" scale="0.001 0.001 0.001" />
            </geometry>
        </visual>
        <collision name="ak60-6v1-1-v1_collision">
            <origin xyz="-0.0006987390328387133 0.0013048524342867353 -0.010395152635370693" rpy="-1.5707963267949223 1.4293577073673651 2.062433385908139" />
            <geometry>
                <mesh filename="meshes/ak60-6v1-1-v1.stl" scale="0.001 0.001 0.001" />
            </geometry>
        </collision>
    </link>
    <link name="구성요소10">
        <inertial>
            <origin xyz="0.0032095486366824845 -0.002407409477700081 0.0019433999253219514" rpy="0.0 -0.0 0.0" />
            <mass value="0.13156890942165747" />
            <inertia ixx="0.0001432170732038177" iyy="7.179762972295452e-05" izz="7.584453178141601e-05" ixy="1.0426751482062635e-05" iyz="6.0138202557307466e-06" ixz="2.8431245891062722e-06" />
        </inertial>
        <visual name="구성요소10_visual">
            <origin xyz="-2.1932652671807774e-09 4.390350634153606e-09 -2.4047515978509183e-09" rpy="-1.4954521335481847 0.48629735574985516 -1.4106597868084287" />
            <geometry>
                <mesh filename="meshes/구성요소10.stl" scale="0.001 0.001 0.001" />
            </geometry>
        </visual>
        <collision name="구성요소10_collision">
            <origin xyz="-2.1932652671807774e-09 4.390350634153606e-09 -2.4047515978509183e-09" rpy="-1.4954521335481847 0.48629735574985516 -1.4106597868084287" />
            <geometry>
                <mesh filename="meshes/구성요소10.stl" scale="0.001 0.001 0.001" />
            </geometry>
        </collision>
    </link>
    <link name="구성요소11">
        <inertial>
            <origin xyz="0.010491685187381635 0.0012762918032657477 0.0006582349991229353" rpy="0.0 -0.0 0.0" />
            <mass value="0.3456856671384452" />
            <inertia ixx="0.0001513350041927014" iyy="8.706918222034857e-05" izz="8.62590722006881e-05" ixy="8.177083101073398e-06" iyz="2.8185900054728136e-07" ixz="4.3851981060551966e-06" />
        </inertial>
        <visual name="구성요소11_visual">
            <origin xyz="-1.5485295534745092e-09 1.546878627411985e-09 -2.7157451243375875e-09" rpy="-1.4693402150096322 0.8539096224606694 -1.3693279149087239" />
            <geometry>
                <mesh filename="meshes/구성요소11.stl" scale="0.001 0.001 0.001" />
            </geometry>
        </visual>
        <collision name="구성요소11_collision">
            <origin xyz="-1.5485295534745092e-09 1.546878627411985e-09 -2.7157451243375875e-09" rpy="-1.4693402150096322 0.8539096224606694 -1.3693279149087239" />
            <geometry>
                <mesh filename="meshes/구성요소11.stl" scale="0.001 0.001 0.001" />
            </geometry>
        </collision>
    </link>
    <link name="ak70-10-v1_1">
        <inertial>
            <origin xyz="-7.146546050766822e-05 7.146546059160694e-05 0.014729945989910722" rpy="0.0 -0.0 0.0" />
            <mass value="2.1429063401431327" />
            <inertia ixx="0.001352590595148548" iyy="0.0013525905928285895" izz="0.001943353163998447" ixy="-3.36623600805629e-06" iyz="3.3580222740980733e-06" ixz="-3.3580222738421545e-06" />
        </inertial>
        <visual name="ak70-10-v1_1_visual">
            <origin xyz="-4.884981308350689e-17 0.0 -0.011199999999999996" rpy="-0.0 1.5707963267948923 0" />
            <geometry>
                <mesh filename="meshes/ak70-10-v1_1.stl" scale="0.001 0.001 0.001" />
            </geometry>
        </visual>
        <collision name="ak70-10-v1_1_collision">
            <origin xyz="-4.884981308350689e-17 0.0 -0.011199999999999996" rpy="-0.0 1.5707963267948923 0" />
            <geometry>
                <mesh filename="meshes/ak70-10-v1_1.stl" scale="0.001 0.001 0.001" />
            </geometry>
        </collision>
    </link>
    <link name="ak70-10-v1_2">
        <inertial>
            <origin xyz="-0.01576396797505715 7.146546049458636e-05 -0.008522553514598324" rpy="0.0 -6.162975822039156e-33 0.0" />
            <mass value="2.1429063401431327" />
            <inertia ixx="0.0018144967868397861" iyy="0.0013525905951486954" izz="0.0014814469699874276" ixy="4.549400242228587e-06" iyz="-1.382322643100951e-06" ixz="0.00024398941587916315" />
        </inertial>
        <visual name="ak70-10-v1_2_visual">
            <origin xyz="-0.038656539843531665 -1.3464784842653899e-14 -0.02070029384679885" rpy="-1.5707963267948986 0.49163705911324945 -3.1415926535897802" />
            <geometry>
                <mesh filename="meshes/ak70-10-v1_2.stl" scale="0.001 0.001 0.001" />
            </geometry>
        </visual>
        <collision name="ak70-10-v1_2_collision">
            <origin xyz="-0.038656539843531665 -1.3464784842653899e-14 -0.02070029384679885" rpy="-1.5707963267948986 0.49163705911324945 -3.1415926535897802" />
            <geometry>
                <mesh filename="meshes/ak70-10-v1_2.stl" scale="0.001 0.001 0.001" />
            </geometry>
        </collision>
    </link>
    <link name="구성요소8_2">
        <inertial>
            <origin xyz="-0.006372309818911987 -0.045117919673216066 0.013489898666210164" rpy="0.0 -0.0 0.0" />
            <mass value="0.668762166036501" />
            <inertia ixx="0.0010148716182495532" iyy="0.00023157548062719725" izz="0.0009036916958036975" ixy="-6.210158613305723e-05" iyz="-6.940763659984625e-05" ixz="-8.91183309438519e-05" />
        </inertial>
        <visual name="구성요소8_2_visual">
            <origin xyz="-0.006208238048647936 -0.09495025999998723 0.005353141743959448" rpy="-1.3133881577013966 -1.0608242926663234 -0.29294959878396315" />
            <geometry>
                <mesh filename="meshes/구성요소8_2.stl" scale="0.001 0.001 0.001" />
            </geometry>
        </visual>
        <collision name="구성요소8_2_collision">
            <origin xyz="-0.006208238048647936 -0.09495025999998723 0.005353141743959448" rpy="-1.3133881577013966 -1.0608242926663234 -0.29294959878396315" />
            <geometry>
                <mesh filename="meshes/구성요소8_2.stl" scale="0.001 0.001 0.001" />
            </geometry>
        </collision>
    </link>
    <joint name="ak60-6v1-1-v1_회전-1" type="continuous">
        <origin xyz="0.0019298499999999997 -0.003603870000000001 0.02871041000000002" rpy="3.141592653589793 -1.5707963267948966 0" />
        <parent link="ak60-6v1-1-v1" />
        <child link="구성요소11" />
        <axis xyz="-0.990014 -0.12427100000000012 -0.066546" />
    </joint>
    <joint name="base_link_강체-4" type="fixed">
        <origin xyz="0.0 0.0 0.023" rpy="0.0 -0.0 0.0" />
        <parent link="base_link" />
        <child link="ak70-10-v1_1" />
    </joint>
    <joint name="ak70-10-v1_1_회전-5" type="continuous">
        <origin xyz="0.0 0.0 0.03905" rpy="-3.141592653589793 -1.5707963267948966 0" />
        <parent link="ak70-10-v1_1" />
        <child link="구성요소2" />
        <axis xyz="-1.0 -0.0 -7.888609052210118e-31" />
    </joint>
    <joint name="구성요소2_강체-6" type="fixed">
        <origin xyz="0.02 0.0 1.5777218104420236e-32" rpy="3.141592653589793 -1.5707963267948966 0" />
        <parent link="구성요소2" />
        <child link="구성요소3" />
    </joint>
    <joint name="구성요소3_강체-7" type="fixed">
        <origin xyz="-0.02998468 0.00095869 0.01800000000000001" rpy="-3.141592653589793 -3.944304526105059e-31 9.800333363043902e-30" />
        <parent link="구성요소3" />
        <child link="구성요소4" />
    </joint>
    <joint name="구성요소4_강체-8" type="fixed">
        <origin xyz="0.04433209 -0.00672424 -0.056999999999999995" rpy="1.5707963267948966 -7.888609052210118e-31 5.551115123118146e-17" />
        <parent link="구성요소4" />
        <child link="ak70-10-v1_2" />
    </joint>
    <joint name="ak70-10-v1_2_회전-9" type="continuous">
        <origin xyz="0.005641909999999999 0.0 0.0030212099999999977" rpy="-1.5707963267948966 -0.0 -1.5707963267948966" />
        <parent link="ak70-10-v1_2" />
        <child link="구성요소5" />
        <axis xyz="-7.447951350553661e-31 0.47207000000000005 -0.881561" />
    </joint>
    <joint name="ak70-10-v1_2_강체-10" type="fixed">
        <origin xyz="-0.02878305 0.0 -0.015413110000000004" rpy="1.5707963267948968 -0.0 -1.5707963267948966" />
        <parent link="ak70-10-v1_2" />
        <child link="구성요소6" />
    </joint>
    <joint name="구성요소5_강체-11" type="fixed">
        <origin xyz="0.03217546 -0.00776292 0.02420179" rpy="1.5707963267948966 -1.5707963267948966 0" />
        <parent link="구성요소5" />
        <child link="구성요소7" />
    </joint>
    <joint name="구성요소7_강체-12" type="fixed">
        <origin xyz="0.007983789999999998 0.012375179999999979 0.006274090000000001" rpy="-1.385805059804159e-19 -5.355483398803478e-17 2.7755575615628907e-17" />
        <parent link="구성요소7" />
        <child link="구성요소8_1" />
    </joint>
    <joint name="ak60-6v1-1-v1_강체-13" type="fixed">
        <origin xyz="0.0018300300000000003 -0.0034174600000000024 0.027225390000000012" rpy="3.141592653589793 -1.5707963267948966 0" />
        <parent link="ak60-6v1-1-v1" />
        <child link="구성요소10" />
    </joint>
    <joint name="구성요소9_강체-16" type="fixed">
        <origin xyz="-0.029460129999999998 0.005041179999999947 0.033954930000000015" rpy="-1.5707963267948966 5.651269022745248e-17 2.775557561562892e-17" />
        <parent link="구성요소9" />
        <child link="ak60-6v1-1-v1" />
    </joint>
    <joint name="구성요소8_1_강체-17" type="fixed">
        <origin xyz="-0.009227670000000004 -0.07514998000000002 0.00028544999999999824" rpy="-3.141592653589793 5.8689517296745976e-18 2.775557561562892e-17" />
        <parent link="구성요소8_1" />
        <child link="구성요소9" />
    </joint>
    <joint name="구성요소9_강체-19" type="fixed">
        <origin xyz="-0.07405115000000001 -3.552713678800501e-17 0.03965385000000001" rpy="-2.71281853479291e-18 5.651269022745248e-17 2.775557561562892e-17" />
        <parent link="구성요소9" />
        <child link="구성요소8_2" />
    </joint>
</robot>