<?xml version="1.0" ?>
<robot name="sfbot" xmlns:xacro="http://www.ros.org/wiki/xacro">

<xacro:macro name="sfbot" params="prefix">

<xacro:include filename="$(find sfbot_description)/urdf/materials.xacro" />
<xacro:include filename="$(find sfbot_description)/urdf/sfbot.trans" />
<xacro:include filename="$(find sfbot_description)/urdf/sfbot.gazebo" />
<link name="${prefix}base_link"/>

<link name="${prefix}ak70-10">
  <inertial>
    <origin xyz="-0.0016330202649602788 0.00021177572381218977 0.13397853453951677" rpy="0 0 0"/>
    <mass value="2.1429063401431327"/>
    <inertia ixx="0.001925" iyy="0.001371" izz="0.001353" ixy="-0.000103" iyz="4e-06" ixz="-3e-06"/>
  </inertial>
  <visual>
    <origin xyz="0 0 0" rpy="0 0 0"/>
    <geometry>
      <mesh filename="package://sfbot_description/meshes/ak70-10.stl" scale="0.001 0.001 0.001"/>
    </geometry>
    <material name="sfbot_silver"/>
  </visual>
  <collision>
    <origin xyz="0 0 0" rpy="0 0 0"/>
    <geometry>
      <mesh filename="package://sfbot_description/meshes/ak70-10.stl" scale="0.001 0.001 0.001"/>
    </geometry>
  </collision>
</link>

<link name="${prefix}Component2">
  <inertial>
    <origin xyz="1.0698387736153028e-05 0.0001253998412609885 0.010945074522193017" rpy="0 0 0"/>
    <mass value="1.0016922735671667"/>
    <inertia ixx="0.000597" iyy="0.000592" izz="0.001126" ixy="-0.0" iyz="1e-06" ixz="0.0"/>
  </inertial>
  <visual>
    <origin xyz="0 0 0" rpy="0 0 0"/>
    <geometry>
      <mesh filename="package://sfbot_description/meshes/Component2.stl" scale="0.001 0.001 0.001"/>
    </geometry>
    <material name="sfbot_silver"/>
  </visual>
  <collision>
    <origin xyz="0 0 0" rpy="0 0 0"/>
    <geometry>
      <mesh filename="package://sfbot_description/meshes/Component2.stl" scale="0.001 0.001 0.001"/>
    </geometry>
  </collision>
</link>

<link name="${prefix}Component3">
  <inertial>
    <origin xyz="0.0016903652155425741 0.00043829643006388806 0.008375687022008707" rpy="0 0 0"/>
    <mass value="0.8807950300955173"/>
    <inertia ixx="0.000498" iyy="0.000545" izz="0.000981" ixy="-1.9e-05" iyz="-6e-06" ixz="-2.1e-05"/>
  </inertial>
  <visual>
    <origin xyz="0 0 0" rpy="0 0 0"/>
    <geometry>
      <mesh filename="package://sfbot_description/meshes/Component3.stl" scale="0.001 0.001 0.001"/>
    </geometry>
    <material name="sfbot_silver"/>
  </visual>
  <collision>
    <origin xyz="0 0 0" rpy="0 0 0"/>
    <geometry>
      <mesh filename="package://sfbot_description/meshes/Component3.stl" scale="0.001 0.001 0.001"/>
    </geometry>
  </collision>
</link>

<link name="${prefix}Component4">
  <inertial>
    <origin xyz="0.0031218985467114263 -0.0005435367118737871 0.019811113493133692" rpy="0 0 0"/>
    <mass value="0.6184682868789885"/>
    <inertia ixx="0.000771" iyy="0.000551" izz="0.000576" ixy="-4e-05" iyz="1.3e-05" ixz="-7.5e-05"/>
  </inertial>
  <visual>
    <origin xyz="0 0 0" rpy="0 0 0"/>
    <geometry>
      <mesh filename="package://sfbot_description/meshes/Component4.stl" scale="0.001 0.001 0.001"/>
    </geometry>
    <material name="sfbot_silver"/>
  </visual>
  <collision>
    <origin xyz="0 0 0" rpy="0 0 0"/>
    <geometry>
      <mesh filename="package://sfbot_description/meshes/Component4.stl" scale="0.001 0.001 0.001"/>
    </geometry>
  </collision>
</link>

<link name="${prefix}ak70-10">
  <inertial>
    <origin xyz="-0.017667020264960278 0.00300377572381219 -7.146546048322766e-05" rpy="0 0 0"/>
    <mass value="2.1429063401431327"/>
    <inertia ixx="0.001925" iyy="0.001371" izz="0.001353" ixy="-0.000103" iyz="4e-06" ixz="-3e-06"/>
  </inertial>
  <visual>
    <origin xyz="0 0 0" rpy="0 0 0"/>
    <geometry>
      <mesh filename="package://sfbot_description/meshes/ak70-10.stl" scale="0.001 0.001 0.001"/>
    </geometry>
    <material name="sfbot_silver"/>
  </visual>
  <collision>
    <origin xyz="0 0 0" rpy="0 0 0"/>
    <geometry>
      <mesh filename="package://sfbot_description/meshes/ak70-10.stl" scale="0.001 0.001 0.001"/>
    </geometry>
  </collision>
</link>

<link name="${prefix}Component6">
  <inertial>
    <origin xyz="-0.014079814936502365 0.0024573459484413225 -0.0028329199465789157" rpy="0 0 0"/>
    <mass value="0.8292297988354185"/>
    <inertia ixx="0.000927" iyy="0.000453" izz="0.000583" ixy="-8.5e-05" iyz="-3e-06" ixz="1.4e-05"/>
  </inertial>
  <visual>
    <origin xyz="0 0 0" rpy="0 0 0"/>
    <geometry>
      <mesh filename="package://sfbot_description/meshes/Component6.stl" scale="0.001 0.001 0.001"/>
    </geometry>
    <material name="sfbot_silver"/>
  </visual>
  <collision>
    <origin xyz="0 0 0" rpy="0 0 0"/>
    <geometry>
      <mesh filename="package://sfbot_description/meshes/Component6.stl" scale="0.001 0.001 0.001"/>
    </geometry>
  </collision>
</link>

<link name="${prefix}Component5">
  <inertial>
    <origin xyz="0.015247398207631529 -0.0019291976053051616 -0.00023131958057376334" rpy="0 0 0"/>
    <mass value="0.6082106863628858"/>
    <inertia ixx="0.000404" iyy="0.000232" izz="0.000242" ixy="-3.3e-05" iyz="6e-06" ixz="2e-06"/>
  </inertial>
  <visual>
    <origin xyz="0 0 0" rpy="0 0 0"/>
    <geometry>
      <mesh filename="package://sfbot_description/meshes/Component5.stl" scale="0.001 0.001 0.001"/>
    </geometry>
    <material name="sfbot_silver"/>
  </visual>
  <collision>
    <origin xyz="0 0 0" rpy="0 0 0"/>
    <geometry>
      <mesh filename="package://sfbot_description/meshes/Component5.stl" scale="0.001 0.001 0.001"/>
    </geometry>
  </collision>
</link>

<link name="${prefix}Component7">
  <inertial>
    <origin xyz="0.00489165778914033 -0.0008520018886194539 1.9817480989559044e-14" rpy="0 0 0"/>
    <mass value="0.3722794963916967"/>
    <inertia ixx="0.000292" iyy="0.000155" izz="0.000151" ixy="-2.4e-05" iyz="0.0" ixz="0.0"/>
  </inertial>
  <visual>
    <origin xyz="0 0 0" rpy="0 0 0"/>
    <geometry>
      <mesh filename="package://sfbot_description/meshes/Component7.stl" scale="0.001 0.001 0.001"/>
    </geometry>
    <material name="sfbot_silver"/>
  </visual>
  <collision>
    <origin xyz="0 0 0" rpy="0 0 0"/>
    <geometry>
      <mesh filename="package://sfbot_description/meshes/Component7.stl" scale="0.001 0.001 0.001"/>
    </geometry>
  </collision>
</link>

<link name="${prefix}Component8_1">
  <inertial>
    <origin xyz="0.0011677996108209326 -0.01652738559923222 0.025721554143796843" rpy="0 0 0"/>
    <mass value="0.668762166036501"/>
    <inertia ixx="0.001049" iyy="0.0007" izz="0.000401" ixy="-7.5e-05" iyz="0.000284" ixz="6.9e-05"/>
  </inertial>
  <visual>
    <origin xyz="0 0 0" rpy="0 0 0"/>
    <geometry>
      <mesh filename="package://sfbot_description/meshes/Component8_1.stl" scale="0.001 0.001 0.001"/>
    </geometry>
    <material name="sfbot_silver"/>
  </visual>
  <collision>
    <origin xyz="0 0 0" rpy="0 0 0"/>
    <geometry>
      <mesh filename="package://sfbot_description/meshes/Component8_1.stl" scale="0.001 0.001 0.001"/>
    </geometry>
  </collision>
</link>

<link name="${prefix}Component9">
  <inertial>
    <origin xyz="-0.043826638726452705 -0.006870528379930629 -0.016898308878394386" rpy="0 0 0"/>
    <mass value="0.6867109263567744"/>
    <inertia ixx="0.000541" iyy="0.000776" izz="0.000969" ixy="4.2e-05" iyz="-0.000192" ixz="-3.3e-05"/>
  </inertial>
  <visual>
    <origin xyz="0 0 0" rpy="0 0 0"/>
    <geometry>
      <mesh filename="package://sfbot_description/meshes/Component9.stl" scale="0.001 0.001 0.001"/>
    </geometry>
    <material name="sfbot_silver"/>
  </visual>
  <collision>
    <origin xyz="0 0 0" rpy="0 0 0"/>
    <geometry>
      <mesh filename="package://sfbot_description/meshes/Component9.stl" scale="0.001 0.001 0.001"/>
    </geometry>
  </collision>
</link>

<link name="${prefix}Component8_2">
  <inertial>
    <origin xyz="-0.01006456202696649 0.012070351438509604 -0.04484644585619865" rpy="0 0 0"/>
    <mass value="0.668762166036501"/>
    <inertia ixx="0.001057" iyy="0.000692" izz="0.000401" ixy="-5.3e-05" iyz="0.00029" ixz="3.1e-05"/>
  </inertial>
  <visual>
    <origin xyz="0 0 0" rpy="0 0 0"/>
    <geometry>
      <mesh filename="package://sfbot_description/meshes/Component8_2.stl" scale="0.001 0.001 0.001"/>
    </geometry>
    <material name="sfbot_silver"/>
  </visual>
  <collision>
    <origin xyz="0 0 0" rpy="0 0 0"/>
    <geometry>
      <mesh filename="package://sfbot_description/meshes/Component8_2.stl" scale="0.001 0.001 0.001"/>
    </geometry>
  </collision>
</link>

<link name="${prefix}ak60-6v1-1">
  <inertial>
    <origin xyz="-0.00101912495277509 -0.005853835964794565 0.009127261065465797" rpy="0 0 0"/>
    <mass value="1.2585201056414106"/>
    <inertia ixx="0.000578" iyy="0.000669" izz="0.000801" ixy="1.6e-05" iyz="-0.00014" ixz="-2.4e-05"/>
  </inertial>
  <visual>
    <origin xyz="0 0 0" rpy="0 0 0"/>
    <geometry>
      <mesh filename="package://sfbot_description/meshes/ak60-6v1-1.stl" scale="0.001 0.001 0.001"/>
    </geometry>
    <material name="sfbot_silver"/>
  </visual>
  <collision>
    <origin xyz="0 0 0" rpy="0 0 0"/>
    <geometry>
      <mesh filename="package://sfbot_description/meshes/ak60-6v1-1.stl" scale="0.001 0.001 0.001"/>
    </geometry>
  </collision>
</link>

<link name="${prefix}Component10">
  <inertial>
    <origin xyz="0.002773688838486546 -0.0006850222834892672 0.0034219477594010783" rpy="0 0 0"/>
    <mass value="0.13156890942165747"/>
    <inertia ixx="6.9e-05" iyy="9.7e-05" izz="0.000125" ixy="1e-06" iyz="-3e-05" ixz="-1e-05"/>
  </inertial>
  <visual>
    <origin xyz="0 0 0" rpy="0 0 0"/>
    <geometry>
      <mesh filename="package://sfbot_description/meshes/Component10.stl" scale="0.001 0.001 0.001"/>
    </geometry>
    <material name="sfbot_silver"/>
  </visual>
  <collision>
    <origin xyz="0 0 0" rpy="0 0 0"/>
    <geometry>
      <mesh filename="package://sfbot_description/meshes/Component10.stl" scale="0.001 0.001 0.001"/>
    </geometry>
  </collision>
</link>

<link name="${prefix}Component11">
  <inertial>
    <origin xyz="-0.0009016152168058143 -0.005530744741957291 0.008985773830917532" rpy="0 0 0"/>
    <mass value="0.3456856671384452"/>
    <inertia ixx="8.6e-05" iyy="0.000104" izz="0.000134" ixy="3e-06" iyz="-2.9e-05" ixz="-5e-06"/>
  </inertial>
  <visual>
    <origin xyz="0 0 0" rpy="0 0 0"/>
    <geometry>
      <mesh filename="package://sfbot_description/meshes/Component11.stl" scale="0.001 0.001 0.001"/>
    </geometry>
    <material name="sfbot_silver"/>
  </visual>
  <collision>
    <origin xyz="0 0 0" rpy="0 0 0"/>
    <geometry>
      <mesh filename="package://sfbot_description/meshes/Component11.stl" scale="0.001 0.001 0.001"/>
    </geometry>
  </collision>
</link>

<joint name="${prefix}fix 1" type="fixed">
  <origin xyz="0.016034 -0.002792 0.15705" rpy="0 0 0"/>
  <parent link="${prefix}base_link"/>
  <child link="${prefix}ak70-10"/>
</joint>

<joint name="${prefix}con 2" type="continuous">
  <origin xyz="-0.016034 0.002792 -0.095" rpy="0 0 0"/>
  <parent link="${prefix}ak70-10"/>
  <child link="${prefix}Component2"/>
  <axis xyz="-0.0 -0.0 -1.0"/>
</joint>

<joint name="${prefix}fix 3" type="fixed">
  <origin xyz="0.0 -0.0 0.02" rpy="0 0 0"/>
  <parent link="${prefix}Component2"/>
  <child link="${prefix}Component3"/>
</joint>

<joint name="${prefix}fix 4" type="fixed">
  <origin xyz="0.0 0.0 0.018" rpy="0 0 0"/>
  <parent link="${prefix}Component3"/>
  <child link="${prefix}Component4"/>
</joint>

<joint name="${prefix}fix 5" type="fixed">
  <origin xyz="0.016034 -0.002792 0.057" rpy="0 0 0"/>
  <parent link="${prefix}Component4"/>
  <child link="${prefix}ak70-10"/>
</joint>

<joint name="${prefix}fix 6" type="fixed">
  <origin xyz="-0.032166 0.005601 0.0" rpy="0 0 0"/>
  <parent link="${prefix}ak70-10"/>
  <child link="${prefix}Component6"/>
</joint>

<joint name="${prefix}con 7" type="continuous">
  <origin xyz="0.006305 -0.001097 0.0" rpy="0 0 0"/>
  <parent link="${prefix}ak70-10"/>
  <child link="${prefix}Component5"/>
  <axis xyz="-0.98518 0.171524 0.0"/>
</joint>

<joint name="${prefix}fix 8" type="fixed">
  <origin xyz="0.024629 -0.004288 0.0" rpy="0 0 0"/>
  <parent link="${prefix}Component5"/>
  <child link="${prefix}Component7"/>
</joint>

<joint name="${prefix}fix 9" type="fixed">
  <origin xyz="0.008034 -0.012161 0.016958" rpy="0 0 0"/>
  <parent link="${prefix}Component7"/>
  <child link="${prefix}Component8_1"/>
</joint>

<joint name="${prefix}fix 10" type="fixed">
  <origin xyz="-0.012384 -0.024486 0.070568" rpy="0 0 0"/>
  <parent link="${prefix}Component8_1"/>
  <child link="${prefix}Component9"/>
</joint>

<joint name="${prefix}fix 11" type="fixed">
  <origin xyz="-0.082755 0.014408 0.0" rpy="0 0 0"/>
  <parent link="${prefix}Component9"/>
  <child link="${prefix}Component8_2"/>
</joint>

<joint name="${prefix}fix 12" type="fixed">
  <origin xyz="-0.044241 -0.009243 -0.001887" rpy="0 0 0"/>
  <parent link="${prefix}Component9"/>
  <child link="${prefix}ak60-6v1-1"/>
</joint>

<joint name="${prefix}fix 13" type="fixed">
  <origin xyz="-0.002501 -0.014363 0.023318" rpy="0 0 0"/>
  <parent link="${prefix}ak60-6v1-1"/>
  <child link="${prefix}Component10"/>
</joint>

<joint name="${prefix}con 14" type="continuous">
  <origin xyz="-0.002637 -0.015146 0.024589" rpy="0 0 0"/>
  <parent link="${prefix}ak60-6v1-1"/>
  <child link="${prefix}Component11"/>
  <axis xyz="0.090932 0.522283 -0.847911"/>
</joint>

</xacro:macro>
</robot>
